Failure # 1 (occurred at 2020-12-06_11-07-03)
Traceback (most recent call last):
  File "/Users/admin/anaconda3/envs/newpy36/lib/python3.6/site-packages/ray/tune/trial_runner.py", line 726, in _process_trial
    result = self.trial_executor.fetch_result(trial)
  File "/Users/admin/anaconda3/envs/newpy36/lib/python3.6/site-packages/ray/tune/ray_trial_executor.py", line 489, in fetch_result
    result = ray.get(trial_future[0], timeout=DEFAULT_GET_TIMEOUT)
  File "/Users/admin/anaconda3/envs/newpy36/lib/python3.6/site-packages/ray/worker.py", line 1452, in get
    raise value.as_instanceof_cause()
ray.exceptions.RayTaskError(TuneError): [36mray::ImplicitFunc.train()[39m (pid=23538, ip=192.168.86.30)
  File "python/ray/_raylet.pyx", line 482, in ray._raylet.execute_task
  File "python/ray/_raylet.pyx", line 436, in ray._raylet.execute_task.function_executor
  File "/Users/admin/anaconda3/envs/newpy36/lib/python3.6/site-packages/ray/tune/trainable.py", line 336, in train
    result = self.step()
  File "/Users/admin/anaconda3/envs/newpy36/lib/python3.6/site-packages/ray/tune/function_runner.py", line 366, in step
    self._report_thread_runner_error(block=True)
  File "/Users/admin/anaconda3/envs/newpy36/lib/python3.6/site-packages/ray/tune/function_runner.py", line 513, in _report_thread_runner_error
    .format(err_tb_str)))
ray.tune.error.TuneError: Trial raised an exception. Traceback:
[36mray::ImplicitFunc.train()[39m (pid=23538, ip=192.168.86.30)
  File "/Users/admin/anaconda3/envs/newpy36/lib/python3.6/site-packages/ray/tune/function_runner.py", line 248, in run
    self._entrypoint()
  File "/Users/admin/anaconda3/envs/newpy36/lib/python3.6/site-packages/ray/tune/function_runner.py", line 316, in entrypoint
    self._status_reporter.get_checkpoint())
  File "/Users/admin/anaconda3/envs/newpy36/lib/python3.6/site-packages/ray/tune/function_runner.py", line 575, in _trainable_func
    output = fn()
  File "/Users/admin/anaconda3/envs/newpy36/lib/python3.6/site-packages/ray/tune/function_runner.py", line 649, in _inner
    inner(config, checkpoint_dir=None)
  File "/Users/admin/anaconda3/envs/newpy36/lib/python3.6/site-packages/ray/tune/function_runner.py", line 643, in inner
    fn(config, **fn_kwargs)
  File "tune_td3.py", line 133, in train
    policy.train(replay_buffer, batch_size)
  File "/Users/admin/703/project/TD3/TD3.py", line 128, in train
  File "/Users/admin/703/project/TD3/TD3.py", line 128, in train
  File "/Users/admin/anaconda3/envs/newpy36/lib/python3.6/bdb.py", line 51, in trace_dispatch
    return self.dispatch_line(frame)
  File "/Users/admin/anaconda3/envs/newpy36/lib/python3.6/bdb.py", line 70, in dispatch_line
    if self.quitting: raise BdbQuit
bdb.BdbQuit

